Workbook

Sheet README
B2: Indeed US Salaries — Excel Portfolio Project
B3: Pivot Tables · What-If Analysis · INDEX/MATCH & Lookup Functions · Macros & VBA
B5: Dataset | C5: 979 rows of median salary data scraped from Indeed, covering 98 US companies and 29 job categories.
B6: Source file | C6: indeed_salaries_us_companies.csv (loaded unedited into the Raw_Data sheet)
B7: Goal | C7: Demonstrate a realistic end-to-end Excel analysis workflow for a portfolio: clean data, look values up, summarize with a pivot table, run what-if / sensitivity analysis, and automate reporting with VBA.
B9: Workbook map
B10: Raw_Data | C10: Original CSV, untouched, as an Excel Table (RawDataTable).
B11: Multiplier_Lookup | C11: Small reference table (HOURLY/WEEKLY/MONTHLY/YEARLY -> annual multiplier) used by INDEX/MATCH.
B12: Cleaned_Data | C12: Raw data + an AnnualSalary column normalized to a yearly figure via INDEX/MATCH, plus a lookup Key column.
B13: Lookup_Exercises | C13: Live INDEX/MATCH, VLOOKUP and HLOOKUP exercises - pick a company/job from dropdowns and watch results update.
B14: Pivot_Summary | C14: A formula-built ('manual') pivot by Category and by Company, plus steps to build a real native PivotTable.
B15: What_If_Analysis | C15: A raise-percentage sensitivity table, Goal Seek setup, and Scenario Manager setup, with click-by-click steps.
B16: Dashboard | C16: KPI cards, a company-selector dropdown, and two charts summarizing the data.
B17: VBA_Macros | C17: Full VBA source for 3 macros (clean & convert data, auto-generate a summary report, refresh the dashboard) + setup steps.
B19: Important note on the VBA/macros
B20: This file is saved as .xlsx, which cannot store runnable macros (Excel requires the .xlsm format for that, and a macro project has to be compiled inside Excel itself). The VBA_Macros sheet contains the complete, ready-to-run source code. To activate it: open this file in Excel, Save As -> 'Excel Macro-Enabled Workbook (*.xlsm)', then press Alt+F11, insert a Module, and paste in the code. Full steps are on that sheet.

Sheet Raw_Data
A1: company | B1: companySlug | C1: category | D1: jobTitle | E1: normalizedJobTitle | F1: medianSalary | G1: medianSalaryText | H1: salaryPeriod | I1: reportedSalaryCount | J1: url | K1: matchedInput
A2: Walmart | B2: Walmart | C2: Pharmacy | D2: Pharmacy Technician | E2: pharmacy technician | F2: 18.71 | G2: $18.71 | H2: HOURLY | I2: 869 | J2: https://www.indeed.com/cmp/Walmart/salaries/Pharmacy-Technician | K2: Walmart
A3: Walmart | B3: Walmart | C3: Pharmacy | D3: Certified Pharmacy Technician | E3: certified pharmacy technician | F3: 20.28 | G3: $20.28 | H3: HOURLY | I3: 612 | J3: https://www.indeed.com/cmp/Walmart/salaries/Certified-Pharmacy-Technician | K3: Walmart
A4: Walmart | B4: Walmart | C4: Pharmacy | D4: Pharmacist | E4: pharmacist | F4: 49.16 | G4: $49.16 | H4: HOURLY | I4: 8 | J4: https://www.indeed.com/cmp/Walmart/salaries/Pharmacist | K4: Walmart
A5: Walmart | B5: Walmart | C5: Pharmacy | D5: Staff Pharmacist | E5: staff pharmacist | F5: 64.3 | G5: $64.30 | H5: HOURLY | I5: 18 | J5: https://www.indeed.com/cmp/Walmart/salaries/Staff-Pharmacist | K5: Walmart
A6: Walmart | B6: Walmart | C6: Pharmacy | D6: Pharmacy Manager | E6: pharmacy manager | F6: 49.06 | G6: $49.06 | H6: HOURLY | I6: 3 | K6: Walmart
A7: Walmart | B7: Walmart | C7: Pharmacy | D7: Pharmacy Assistant | E7: pharmacy assistant | F7: 16.12 | G7: $16.12 | H7: HOURLY | I7: 40 | J7: https://www.indeed.com/cmp/Walmart/salaries/Pharmacy-Assistant | K7: Walmart
A8: Walmart | B8: Walmart | C8: Pharmacy | D8: Pharmacy Intern | E8: pharmacy intern | F8: 23.75 | G8: $23.75 | H8: HOURLY | I8: 23 | J8: https://www.indeed.com/cmp/Walmart/salaries/Pharmacy-Intern | K8: Walmart
A9: Walmart | B9: Walmart | C9: Pharmacy | D9: Pharmacist in Charge | E9: pharmacist in charge | F9: 59.53 | G9: $59.53 | H9: HOURLY | I9: 8 | J9: https://www.indeed.com/cmp/Walmart/salaries/Pharmacist-in-Charge | K9: Walmart
A10: Walmart | B10: Walmart | C10: Pharmacy | D10: Pharmacy Clerk | E10: pharmacy clerk | F10: 17.79 | G10: $17.79 | H10: HOURLY | I10: 5 | K10: Walmart
A11: Walmart | B11: Walmart | C11: Pharmacy | D11: Pharmacy Technician Intern | E11: pharmacy technician intern | F11: 17.32 | G11: $17.32 | H11: HOURLY | I11: 1 | K11: Walmart
A12: Amazon.com | B12: Amazon | C12: Loading and Stocking | D12: Warehouse Worker | E12: warehouse worker | F12: 18.49 | G12: $18.49 | H12: HOURLY | I12: 68 | J12: https://www.indeed.com/cmp/Amazon.com/salaries/Warehouse-Worker | K12: Amazon
A13: Amazon.com | B13: Amazon | C13: Loading and Stocking | D13: Warehouse Associate | E13: warehouse associate | F13: 19.28 | G13: $19.28 | H13: HOURLY | I13: 196 | J13: https://www.indeed.com/cmp/Amazon.com/salaries/Warehouse-Associate | K13: Amazon
A14: Amazon.com | B14: Amazon | C14: Loading and Stocking | D14: Fulfillment Associate | E14: fulfillment associate | F14: 19.21 | G14: $19.21 | H14: HOURLY | I14: 173 | J14: https://www.indeed.com/cmp/Amazon.com/salaries/Fulfillment-Associate | K14: Amazon
A15: Amazon.com | B15: Amazon | C15: Loading and Stocking | D15: Packer | E15: packer | F15: 19.19 | G15: $19.19 | H15: HOURLY | I15: 5 | K15: Amazon
A16: Amazon.com | B16: Amazon | C16: Loading and Stocking | D16: Order Picker | E16: order picker | F16: 18.39 | G16: $18.39 | H16: HOURLY | I16: 14 | J16: https://www.indeed.com/cmp/Amazon.com/salaries/Order-Picker | K16: Amazon
A17: Amazon.com | B17: Amazon | C17: Loading and Stocking | D17: Stower | E17: stower | F17: 18.07 | G17: $18.07 | H17: HOURLY | I17: 25 | J17: https://www.indeed.com/cmp/Amazon.com/salaries/Stower | K17: Amazon
A18: Amazon.com | B18: Amazon | C18: Loading and Stocking | D18: Package Handler | E18: package handler | F18: 18.18 | G18: $18.18 | H18: HOURLY | I18: 9 | J18: https://www.indeed.com/cmp/Amazon.com/salaries/Package-Handler | K18: Amazon
A19: Amazon.com | B19: Amazon | C19: Loading and Stocking | D19: Merchandise Flow Team Member | E19: merchandise flow team member | F19: 25.15 | G19: $25.15 | H19: HOURLY | I19: 4 | K19: Amazon
A20: Amazon.com | B20: Amazon | C20: Loading and Stocking | D20: Sorter | E20: sorter | F20: 17.72 | G20: $17.72 | H20: HOURLY | I20: 6 | J20: https://www.indeed.com/cmp/Amazon.com/salaries/Sorter | K20: Amazon
A21: Amazon.com | B21: Amazon | C21: Loading and Stocking | D21: Problem Solver | E21: problem solver | F21: 17.1 | G21: $17.10 | H21: HOURLY | I21: 6 | J21: https://www.indeed.com/cmp/Amazon.com/salaries/Problem-Solver | K21: Amazon
A22: McDonald's | B22: McDonald's | C22: Instalación y mantenimiento | D22: Maintenance Person | E22: maintenance person | F22: 16.23 | G22: $16.23 | H22: HOURLY | I22: 353 | J22: https://www.indeed.com/cmp/McDonald's/salaries/Maintenance-Person | K22: McDonald's
A23: McDonald's | B23: McDonald's | C23: Instalación y mantenimiento | D23: HVAC Technician | E23: hvac technician | F23: 21.35 | G23: $21.35 | H23: HOURLY | I23: 1 | K23: McDonald's
A24: McDonald's | B24: McDonald's | C24: Instalación y mantenimiento | D24: Maintenance Technician | E24: maintenance technician | F24: 18.94 | G24: $18.94 | H24: HOURLY | I24: 18 | J24: https://www.indeed.com/cmp/McDonald's/salaries/Maintenance-Technician | K24: McDonald's
A25: McDonald's | B25: McDonald's | C25: Instalación y mantenimiento | D25: Building Maintenance | E25: building maintenance | F25: 20.2 | G25: $20.20 | H25: HOURLY | I25: 113 | J25: https://www.indeed.com/cmp/McDonald's/salaries/Building-Maintenance | K25: McDonald's
A26: McDonald's | B26: McDonald's | C26: Instalación y mantenimiento | D26: Groundskeeper | E26: groundskeeper | F26: 13.76 | G26: $13.76 | H26: HOURLY | I26: 19 | J26: https://www.indeed.com/cmp/McDonald's/salaries/Groundskeeper | K26: McDonald's
A27: McDonald's | B27: McDonald's | C27: Instalación y mantenimiento | D27: Equipment Repair Technician | E27: equipment repair technician | F27: 26.83 | G27: $26.83 | H27: HOURLY | I27: 19 | J27: https://www.indeed.com/cmp/McDonald's/salaries/Equipment-Repair-Technician | K27: McDonald's
A28: McDonald's | B28: McDonald's | C28: Instalación y mantenimiento | D28: Refrigeration Technician | E28: refrigeration technician | F28: 37.03 | G28: $37.03 | H28: HOURLY | I28: 5 | K28: McDonald's
A29: McDonald's | B29: McDonald's | C29: Instalación y mantenimiento | D29: Facilities Maintenance Technician | E29: facilities maintenance technician | F29: 20.09 | G29: $20.09 | H29: HOURLY | I29: 9 | J29: https://www.indeed.com/cmp/McDonald's/salaries/Facilities-Maintenance-Technician | K29: McDonald's
A30: McDonald's | B30: McDonald's | C30: Instalación y mantenimiento | D30: Equipment Technician | E30: equipment technician | F30: 26.86 | G30: $26.86 | H30: HOURLY | I30: 5 | K30: McDonald's
A31: McDonald's | B31: McDonald's | C31: Instalación y mantenimiento | D31: Field Service Technician | E31: field service technician | F31: 22 | G31: $22.00 | H31: HOURLY | I31: 5 | K31: McDonald's
A32: Target | B32: Target | C32: Food Preparation & Service | D32: Barista | E32: barista | F32: 16.16 | G32: $16.16 | H32: HOURLY | I32: 57 | J32: https://www.indeed.com/cmp/Target/salaries/Barista | K32: Target
A33: Target | B33: Target | C33: Food Preparation & Service | D33: Food & Beverage Team Leader | E33: food & beverage team leader | F33: 29.19 | G33: $29.19 | H33: HOURLY | I33: 21 | J33: https://www.indeed.com/cmp/Target/salaries/Food-&-Beverage-Team-Leader | K33: Target
A34: Target | B34: Target | C34: Food Preparation & Service | D34: Back of House Team Member | E34: back of house team member | F34: 10.8 | G34: $10.80 | H34: HOURLY | I34: 32 | J34: https://www.indeed.com/cmp/Target/salaries/Back-of-House-Team-Member | K34: Target
A35: Target | B35: Target | C35: Food Preparation & Service | D35: Service Leader | E35: service leader | F35: 28.26 | G35: $28.26 | H35: HOURLY | I35: 19 | J35: https://www.indeed.com/cmp/Target/salaries/Service-Leader | K35: Target
A36: Target | B36: Target | C36: Food Preparation & Service | D36: Food Service Worker | E36: food service worker | F36: 16.29 | G36: $16.29 | H36: HOURLY | I36: 10 | J36: https://www.indeed.com/cmp/Target/salaries/Food-Service-Worker | K36: Target
A37: Target | B37: Target | C37: Food Preparation & Service | D37: Deli Associate | E37: deli associate | F37: 14.76 | G37: $14.76 | H37: HOURLY | I37: 8 | J37: https://www.indeed.com/cmp/Target/salaries/Deli-Associate | K37: Target
A38: Target | B38: Target | C38: Food Preparation & Service | D38: Food Service Associate | E38: food service associate | F38: 16.87 | G38: $16.87 | H38: HOURLY | I38: 7 | J38: https://www.indeed.com/cmp/Target/salaries/Food-Service-Associate | K38: Target
A39: Target | B39: Target | C39: Food Preparation & Service | D39: Director of Food and Beverage | E39: director of food and beverage | F39: 17.2 | G39: $17.20 | H39: HOURLY | I39: 4 | K39: Target
A40: Target | B40: Target | C40: Food Preparation & Service | D40: Bakery Team Leader | E40: bakery team leader | F40: 23.05 | G40: $23.05 | H40: HOURLY | I40: 2 | K40: Target
...

Sheet Multiplier_Lookup
B2: Pay-period -> Annual multiplier reference table
B5: Period | C5: Multiplier | D5: Basis
B6: HOURLY | C6: 2080 | D6: 40 hrs/week x 52 weeks
B7: WEEKLY | C7: 52 | D7: 52 weeks/year
B8: MONTHLY | C8: 12 | D8: 12 months/year
B9: YEARLY | C9: 1 | D9: already annual
B13: Period | C13: HOURLY | D13: WEEKLY | E13: MONTHLY | F13: YEARLY
B14: Multiplier | C14: =INDEX($C$6:$C$9,MATCH(C13,$B$6:$B$9,0)) -> 2080 | D14: =INDEX($C$6:$C$9,MATCH(D13,$B$6:$B$9,0)) -> 52 | E14: =INDEX($C$6:$C$9,MATCH(E13,$B$6:$B$9,0)) -> 12 | F14: =INDEX($C$6:$C$9,MATCH(F13,$B$6:$B$9,0)) -> 1

Sheet Cleaned_Data
A1: Company | B1: Category | C1: JobTitle | D1: MedianSalary | E1: SalaryPeriod | F1: ReportedCount | G1: AnnualSalary | H1: Key
A2: =Raw_Data!A2 -> Walmart | B2: =Raw_Data!C2 -> Pharmacy | C2: =Raw_Data!D2 -> Pharmacy Technician | D2: =Raw_Data!F2 -> 18.71 | E2: =Raw_Data!H2 -> HOURLY | F2: =Raw_Data!I2 -> 869 | G2: =D2*INDEX(Multiplier_Lookup!$C$6:$C$9,MATCH(E2,Multiplier_Lookup!$B$6:$B$9,0)) -> 38916.8 | H2: =A2&"|"&C2 -> Walmart|Pharmacy Technician
A3: =Raw_Data!A3 -> Walmart | B3: =Raw_Data!C3 -> Pharmacy | C3: =Raw_Data!D3 -> Certified Pharmacy Technician | D3: =Raw_Data!F3 -> 20.28 | E3: =Raw_Data!H3 -> HOURLY | F3: =Raw_Data!I3 -> 612 | G3: =D3*INDEX(Multiplier_Lookup!$C$6:$C$9,MATCH(E3,Multiplier_Lookup!$B$6:$B$9,0)) -> 42182.4 | H3: =A3&"|"&C3 -> Walmart|Certified Pharmacy Technician
A4: =Raw_Data!A4 -> Walmart | B4: =Raw_Data!C4 -> Pharmacy | C4: =Raw_Data!D4 -> Pharmacist | D4: =Raw_Data!F4 -> 49.16 | E4: =Raw_Data!H4 -> HOURLY | F4: =Raw_Data!I4 -> 8 | G4: =D4*INDEX(Multiplier_Lookup!$C$6:$C$9,MATCH(E4,Multiplier_Lookup!$B$6:$B$9,0)) -> 102252.8 | H4: =A4&"|"&C4 -> Walmart|Pharmacist
A5: =Raw_Data!A5 -> Walmart | B5: =Raw_Data!C5 -> Pharmacy | C5: =Raw_Data!D5 -> Staff Pharmacist | D5: =Raw_Data!F5 -> 64.3 | E5: =Raw_Data!H5 -> HOURLY | F5: =Raw_Data!I5 -> 18 | G5: =D5*INDEX(Multiplier_Lookup!$C$6:$C$9,MATCH(E5,Multiplier_Lookup!$B$6:$B$9,0)) -> 133744 | H5: =A5&"|"&C5 -> Walmart|Staff Pharmacist
A6: =Raw_Data!A6 -> Walmart | B6: =Raw_Data!C6 -> Pharmacy | C6: =Raw_Data!D6 -> Pharmacy Manager | D6: =Raw_Data!F6 -> 49.06 | E6: =Raw_Data!H6 -> HOURLY | F6: =Raw_Data!I6 -> 3 | G6: =D6*INDEX(Multiplier_Lookup!$C$6:$C$9,MATCH(E6,Multiplier_Lookup!$B$6:$B$9,0)) -> 102044.8 | H6: =A6&"|"&C6 -> Walmart|Pharmacy Manager
A7: =Raw_Data!A7 -> Walmart | B7: =Raw_Data!C7 -> Pharmacy | C7: =Raw_Data!D7 -> Pharmacy Assistant | D7: =Raw_Data!F7 -> 16.12 | E7: =Raw_Data!H7 -> HOURLY | F7: =Raw_Data!I7 -> 40 | G7: =D7*INDEX(Multiplier_Lookup!$C$6:$C$9,MATCH(E7,Multiplier_Lookup!$B$6:$B$9,0)) -> 33529.6 | H7: =A7&"|"&C7 -> Walmart|Pharmacy Assistant
A8: =Raw_Data!A8 -> Walmart | B8: =Raw_Data!C8 -> Pharmacy | C8: =Raw_Data!D8 -> Pharmacy Intern | D8: =Raw_Data!F8 -> 23.75 | E8: =Raw_Data!H8 -> HOURLY | F8: =Raw_Data!I8 -> 23 | G8: =D8*INDEX(Multiplier_Lookup!$C$6:$C$9,MATCH(E8,Multiplier_Lookup!$B$6:$B$9,0)) -> 49400 | H8: =A8&"|"&C8 -> Walmart|Pharmacy Intern
A9: =Raw_Data!A9 -> Walmart | B9: =Raw_Data!C9 -> Pharmacy | C9: =Raw_Data!D9 -> Pharmacist in Charge | D9: =Raw_Data!F9 -> 59.53 | E9: =Raw_Data!H9 -> HOURLY | F9: =Raw_Data!I9 -> 8 | G9: =D9*INDEX(Multiplier_Lookup!$C$6:$C$9,MATCH(E9,Multiplier_Lookup!$B$6:$B$9,0)) -> 123822.4 | H9: =A9&"|"&C9 -> Walmart|Pharmacist in Charge
A10: =Raw_Data!A10 -> Walmart | B10: =Raw_Data!C10 -> Pharmacy | C10: =Raw_Data!D10 -> Pharmacy Clerk | D10: =Raw_Data!F10 -> 17.79 | E10: =Raw_Data!H10 -> HOURLY | F10: =Raw_Data!I10 -> 5 | G10: =D10*INDEX(Multiplier_Lookup!$C$6:$C$9,MATCH(E10,Multiplier_Lookup!$B$6:$B$9,0)) -> 37003.2 | H10: =A10&"|"&C10 -> Walmart|Pharmacy Clerk
A11: =Raw_Data!A11 -> Walmart | B11: =Raw_Data!C11 -> Pharmacy | C11: =Raw_Data!D11 -> Pharmacy Technician Intern | D11: =Raw_Data!F11 -> 17.32 | E11: =Raw_Data!H11 -> HOURLY | F11: =Raw_Data!I11 -> 1 | G11: =D11*INDEX(Multiplier_Lookup!$C$6:$C$9,MATCH(E11,Multiplier_Lookup!$B$6:$B$9,0)) -> 36025.6 | H11: =A11&"|"&C11 -> Walmart|Pharmacy Technician Intern
A12: =Raw_Data!A12 -> Amazon.com | B12: =Raw_Data!C12 -> Loading and Stocking | C12: =Raw_Data!D12 -> Warehouse Worker | D12: =Raw_Data!F12 -> 18.49 | E12: =Raw_Data!H12 -> HOURLY | F12: =Raw_Data!I12 -> 68 | G12: =D12*INDEX(Multiplier_Lookup!$C$6:$C$9,MATCH(E12,Multiplier_Lookup!$B$6:$B$9,0)) -> 38459.2 | H12: =A12&"|"&C12 -> Amazon.com|Warehouse Worker
A13: =Raw_Data!A13 -> Amazon.com | B13: =Raw_Data!C13 -> Loading and Stocking | C13: =Raw_Data!D13 -> Warehouse Associate | D13: =Raw_Data!F13 -> 19.28 | E13: =Raw_Data!H13 -> HOURLY | F13: =Raw_Data!I13 -> 196 | G13: =D13*INDEX(Multiplier_Lookup!$C$6:$C$9,MATCH(E13,Multiplier_Lookup!$B$6:$B$9,0)) -> 40102.4 | H13: =A13&"|"&C13 -> Amazon.com|Warehouse Associate
... A980: =Raw_Data!A980 -> Ross Dress For Less | B980: =Raw_Data!C980 -> Loading and Stocking | C980: =Raw_Data!D980 -> Stocker | D980: =Raw_Data!F980 -> 12.3 | E980: =Raw_Data!H980 -> HOURLY | F980: =Raw_Data!I980 -> 30 | G980: =D980*INDEX(Multiplier_Lookup!$C$6:$C$9,MATCH(E980,Multiplier_Lookup!$B$6:$B$9,0)) -> 25584 | H980: =A980&"|"&C980 -> Ross Dress For Less|Stocker

Sheet Lookup_Exercises
B2: Lookup Function
B3: Yellow cells are inputs
B5: A. INDEX/MATCH — exact match on Company + Job Title
B7: Company: | C7: 7-Eleven
B8: Job Title: | C8: Assistant Manager
B10: Lookup Key (=Company&"|"&JobTitle): | C10: =C7&"|"&C8 -> 7-Eleven|Assistant Manager
B12: Category (INDEX/MATCH): | C12: =IFERROR(INDEX(Cleaned_Data!B:B,MATCH(C10,Cleaned_Data!H:H,0)),"No exact match - check spelling") -> Management
B13: Annual Salary (INDEX/MATCH): | C13: =IFERROR(INDEX(Cleaned_Data!G:G,MATCH(C10,Cleaned_Data!H:H,0)),"No exact match - check spelling") -> 36275.2
B16: B. VLOOKUP — first row match on Company (single criterion)
B18: Company: | C18: 7-Eleven
B20: First matching Job Title (VLOOKUP col 4 of Raw_Data): | C20: =IFERROR(VLOOKUP(C18,Raw_Data!$A:$K,4,FALSE()),"Not found") -> Assistant Manager
B21: That row's Category (VLOOKUP col 3): | C21: =IFERROR(VLOOKUP(C18,Raw_Data!$A:$K,3,FALSE()),"Not found") -> Management
B25: C. HLOOKUP — horizontal lookup on pay period
B27: Pay Period: | C27: HOURLY
B28: Annual Multiplier (HLOOKUP): | C28: =HLOOKUP(C27,Multiplier_Lookup!$C$13:$F$14,2,FALSE()) -> 2080

Sheet Pivot_Summary
B2: Pivot Summary
B3: A formula-built summary (SUMIFS/AVERAGEIFS/COUNTIFS) — plus how to build a real, refreshable native PivotTable.
B5: Summary by Category
B6: Category | C6: Job Count | D6: Avg Annual Salary | E6: Min Annual Salary | F6: Max Annual Salary | G6: Total Reported Count
B7: Arts & Entertainment | C7: =COUNTIF(Cleaned_Data!$B:$B,$B7) -> 1 | D7: =AVERAGEIF(Cleaned_Data!$B:$B,$B7,Cleaned_Data!$G:$G) -> 163041 | E7: =_xlfn.MINIFS(Cleaned_Data!$G:$G,Cleaned_Data!$B:$B,$B7) -> 163041 | F7: =_xlfn.MAXIFS(Cleaned_Data!$G:$G,Cleaned_Data!$B:$B,$B7) -> 163041 | G7: =SUMIF(Cleaned_Data!$B:$B,$B7,Cleaned_Data!$F:$F) -> 6
B8: IT Operations & Helpdesk | C8: =COUNTIF(Cleaned_Data!$B:$B,$B8) -> 4 | D8: =AVERAGEIF(Cleaned_Data!$B:$B,$B8,Cleaned_Data!$G:$G) -> 159714.7 | E8: =_xlfn.MINIFS(Cleaned_Data!$G:$G,Cleaned_Data!$B:$B,$B8) -> 55452.8 | F8: =_xlfn.MAXIFS(Cleaned_Data!$G:$G,Cleaned_Data!$B:$B,$B8) -> 228480 | G8: =SUMIF(Cleaned_Data!$B:$B,$B8,Cleaned_Data!$F:$F) -> 56
B9: Project Management | C9: =COUNTIF(Cleaned_Data!$B:$B,$B9) -> 3 | D9: =AVERAGEIF(Cleaned_Data!$B:$B,$B9,Cleaned_Data!$G:$G) -> 154863.33 | E9: =_xlfn.MINIFS(Cleaned_Data!$G:$G,Cleaned_Data!$B:$B,$B9) -> 126647 | F9: =_xlfn.MAXIFS(Cleaned_Data!$G:$G,Cleaned_Data!$B:$B,$B9) -> 169006 | G9: =SUMIF(Cleaned_Data!$B:$B,$B9,Cleaned_Data!$F:$F) -> 33
B10: Software Development | C10: =COUNTIF(Cleaned_Data!$B:$B,$B10) -> 71 | D10: =AVERAGEIF(Cleaned_Data!$B:$B,$B10,Cleaned_Data!$G:$G) -> 129481.72 | E10: =_xlfn.MINIFS(Cleaned_Data!$G:$G,Cleaned_Data!$B:$B,$B10) -> 69867.2 | F10: =_xlfn.MAXIFS(Cleaned_Data!$G:$G,Cleaned_Data!$B:$B,$B10) -> 226707 | G10: =SUMIF(Cleaned_Data!$B:$B,$B10,Cleaned_Data!$F:$F) -> 938
B11: Marketing | C11: =COUNTIF(Cleaned_Data!$B:$B,$B11) -> 14 | D11: =AVERAGEIF(Cleaned_Data!$B:$B,$B11,Cleaned_Data!$G:$G) -> 118235.29 | E11: =_xlfn.MINIFS(Cleaned_Data!$G:$G,Cleaned_Data!$B:$B,$B11) -> 30264 | F11: =_xlfn.MAXIFS(Cleaned_Data!$G:$G,Cleaned_Data!$B:$B,$B11) -> 272049 | G11: =SUMIF(Cleaned_Data!$B:$B,$B11,Cleaned_Data!$F:$F) -> 121
B12: Management | C12: =COUNTIF(Cleaned_Data!$B:$B,$B12) -> 200 | D12: =AVERAGEIF(Cleaned_Data!$B:$B,$B12,Cleaned_Data!$G:$G) -> 114841.14 | E12: =_xlfn.MINIFS(Cleaned_Data!$G:$G,Cleaned_Data!$B:$B,$B12) -> 15000 | F12: =_xlfn.MAXIFS(Cleaned_Data!$G:$G,Cleaned_Data!$B:$B,$B12) -> 370098 | G12: =SUMIF(Cleaned_Data!$B:$B,$B12,Cleaned_Data!$F:$F) -> 3117
B13: Information Design & Documentation | C13: =COUNTIF(Cleaned_Data!$B:$B,$B13) -> 35 | D13: =AVERAGEIF(Cleaned_Data!$B:$B,$B13,Cleaned_Data!$G:$G) -> 114279.57 | E13: =_xlfn.MINIFS(Cleaned_Data!$G:$G,Cleaned_Data!$B:$B,$B13) -> 51627 | F13: =_xlfn.MAXIFS(Cleaned_Data!$G:$G,Cleaned_Data!$B:$B,$B13) -> 240303 | G13: =SUMIF(Cleaned_Data!$B:$B,$B13,Cleaned_Data!$F:$F) -> 1148
B14: Mathematics | C14: =COUNTIF(Cleaned_Data!$B:$B,$B14) -> 52 | D14: =AVERAGEIF(Cleaned_Data!$B:$B,$B14,Cleaned_Data!$G:$G) -> 110308.44 | E14: =_xlfn.MINIFS(Cleaned_Data!$G:$G,Cleaned_Data!$B:$B,$B14) -> 56911 | F14: =_xlfn.MAXIFS(Cleaned_Data!$G:$G,Cleaned_Data!$B:$B,$B14) -> 210356 | G14: =SUMIF(Cleaned_Data!$B:$B,$B14,Cleaned_Data!$F:$F) -> 823
B15: Medical Technician | C15: =COUNTIF(Cleaned_Data!$B:$B,$B15) -> 20 | D15: =AVERAGEIF(Cleaned_Data!$B:$B,$B15,Cleaned_Data!$G:$G) -> 98360.08 | E15: =_xlfn.MINIFS(Cleaned_Data!$G:$G,Cleaned_Data!$B:$B,$B15) -> 47299.2 | F15: =_xlfn.MAXIFS(Cleaned_Data!$G:$G,Cleaned_Data!$B:$B,$B15) -> 388960 | G15: =SUMIF(Cleaned_Data!$B:$B,$B15,Cleaned_Data!$F:$F) -> 137
B16: Sales | C16: =COUNTIF(Cleaned_Data!$B:$B,$B16) -> 86 | D16: =AVERAGEIF(Cleaned_Data!$B:$B,$B16,Cleaned_Data!$G:$G) -> 97496.628 | E16: =_xlfn.MINIFS(Cleaned_Data!$G:$G,Cleaned_Data!$B:$B,$B16) -> 24960 | F16: =_xlfn.MAXIFS(Cleaned_Data!$G:$G,Cleaned_Data!$B:$B,$B16) -> 423415 | G16: =SUMIF(Cleaned_Data!$B:$B,$B16,Cleaned_Data!$F:$F) -> 4539
B17: Banking & Finance | C17: =COUNTIF(Cleaned_Data!$B:$B,$B17) -> 20 | D17: =AVERAGEIF(Cleaned_Data!$B:$B,$B17,Cleaned_Data!$G:$G) -> 97344.58 | E17: =_xlfn.MINIFS(Cleaned_Data!$G:$G,Cleaned_Data!$B:$B,$B17) -> 42182.4 | F17: =_xlfn.MAXIFS(Cleaned_Data!$G:$G,Cleaned_Data!$B:$B,$B17) -> 194315 | G17: =SUMIF(Cleaned_Data!$B:$B,$B17,Cleaned_Data!$F:$F) -> 274
B18: Administrative Assistance | C18: =COUNTIF(Cleaned_Data!$B:$B,$B18) -> 16 | D18: =AVERAGEIF(Cleaned_Data!$B:$B,$B18,Cleaned_Data!$G:$G) -> 91487.713 | E18: =_xlfn.MINIFS(Cleaned_Data!$G:$G,Cleaned_Data!$B:$B,$B18) -> 41308.8 | F18: =_xlfn.MAXIFS(Cleaned_Data!$G:$G,Cleaned_Data!$B:$B,$B18) -> 201224 | G18: =SUMIF(Cleaned_Data!$B:$B,$B18,Cleaned_Data!$F:$F) -> 84
... B35: Cleaning & Sanitation | C35: =COUNTIF(Cleaned_Data!$B:$B,$B35) -> 7 | D35: =AVERAGEIF(Cleaned_Data!$B:$B,$B35,Cleaned_Data!$G:$G) -> 34090.257 | E35: =_xlfn.MINIFS(Cleaned_Data!$G:$G,Cleaned_Data!$B:$B,$B35) -> 25729.6 | F35: =_xlfn.MAXIFS(Cleaned_Data!$G:$G,Cleaned_Data!$B:$B,$B35) -> 42883 | G35: =SUMIF(Cleaned_Data!$B:$B,$B35,Cleaned_Data!$F:$F) -> 84
B38: Summary by Company
B39: Company | C39: Job Count | D39: Avg Annual Salary | E39: Min Annual Salary | F39: Max Annual Salary | G39: Total Reported Count
B40: Adobe | C40: =COUNTIF(Cleaned_Data!$A:$A,$B40) -> 10 | D40: =AVERAGEIF(Cleaned_Data!$A:$A,$B40,Cleaned_Data!$G:$G) -> 213921.44 | E40: =_xlfn.MINIFS(Cleaned_Data!$G:$G,Cleaned_Data!$A:$A,$B40) -> 65686.4 | F40: =_xlfn.MAXIFS(Cleaned_Data!$G:$G,Cleaned_Data!$A:$A,$B40) -> 370098 | G40: =SUMIF(Cleaned_Data!$A:$A,$B40,Cleaned_Data!$F:$F) -> 42
B41: Airbnb | C41: =COUNTIF(Cleaned_Data!$A:$A,$B41) -> 10 | D41: =AVERAGEIF(Cleaned_Data!$A:$A,$B41,Cleaned_Data!$G:$G) -> 197383.7 | E41: =_xlfn.MINIFS(Cleaned_Data!$G:$G,Cleaned_Data!$A:$A,$B41) -> 135622 | F41: =_xlfn.MAXIFS(Cleaned_Data!$G:$G,Cleaned_Data!$A:$A,$B41) -> 308137 | G41: =SUMIF(Cleaned_Data!$A:$A,$B41,Cleaned_Data!$F:$F) -> 47
B42: Salesforce | C42: =COUNTIF(Cleaned_Data!$A:$A,$B42) -> 10 | D42: =AVERAGEIF(Cleaned_Data!$A:$A,$B42,Cleaned_Data!$G:$G) -> 195886.4 | E42: =_xlfn.MINIFS(Cleaned_Data!$G:$G,Cleaned_Data!$A:$A,$B42) -> 81060 | F42: =_xlfn.MAXIFS(Cleaned_Data!$G:$G,Cleaned_Data!$A:$A,$B42) -> 304715 | G42: =SUMIF(Cleaned_Data!$A:$A,$B42,Cleaned_Data!$F:$F) -> 100
B43: PayPal | C43: =COUNTIF(Cleaned_Data!$A:$A,$B43) -> 10 | D43: =AVERAGEIF(Cleaned_Data!$A:$A,$B43,Cleaned_Data!$G:$G) -> 162608.6 | E43: =_xlfn.MINIFS(Cleaned_Data!$G:$G,Cleaned_Data!$A:$A,$B43) -> 38647 | F43: =_xlfn.MAXIFS(Cleaned_Data!$G:$G,Cleaned_Data!$A:$A,$B43) -> 423415 | G43: =SUMIF(Cleaned_Data!$A:$A,$B43,Cleaned_Data!$F:$F) -> 42
B44: Intel Corporation | C44: =COUNTIF(Cleaned_Data!$A:$A,$B44) -> 10 | D44: =AVERAGEIF(Cleaned_Data!$A:$A,$B44,Cleaned_Data!$G:$G) -> 156559.8 | E44: =_xlfn.MINIFS(Cleaned_Data!$G:$G,Cleaned_Data!$A:$A,$B44) -> 68804 | F44: =_xlfn.MAXIFS(Cleaned_Data!$G:$G,Cleaned_Data!$A:$A,$B44) -> 269645 | G44: =SUMIF(Cleaned_Data!$A:$A,$B44,Cleaned_Data!$F:$F) -> 91
B45: Tesla | C45: =COUNTIF(Cleaned_Data!$A:$A,$B45) -> 10 | D45: =AVERAGEIF(Cleaned_Data!$A:$A,$B45,Cleaned_Data!$G:$G) -> 151997.06 | E45: =_xlfn.MINIFS(Cleaned_Data!$G:$G,Cleaned_Data!$A:$A,$B45) -> 102065.6 | F45: =_xlfn.MAXIFS(Cleaned_Data!$G:$G,Cleaned_Data!$A:$A,$B45) -> 226707 | G45: =SUMIF(Cleaned_Data!$A:$A,$B45,Cleaned_Data!$F:$F) -> 133
B46: Dell Technologies | C46: =COUNTIF(Cleaned_Data!$A:$A,$B46) -> 10 | D46: =AVERAGEIF(Cleaned_Data!$A:$A,$B46,Cleaned_Data!$G:$G) -> 148389.7 | E46: =_xlfn.MINIFS(Cleaned_Data!$G:$G,Cleaned_Data!$A:$A,$B46) -> 46998 | F46: =_xlfn.MAXIFS(Cleaned_Data!$G:$G,Cleaned_Data!$A:$A,$B46) -> 261472 | G46: =SUMIF(Cleaned_Data!$A:$A,$B46,Cleaned_Data!$F:$F) -> 135
B47: EY | C47: =COUNTIF(Cleaned_Data!$A:$A,$B47) -> 10 | D47: =AVERAGEIF(Cleaned_Data!$A:$A,$B47,Cleaned_Data!$G:$G) -> 145721.3 | E47: =_xlfn.MINIFS(Cleaned_Data!$G:$G,Cleaned_Data!$A:$A,$B47) -> 90563 | F47: =_xlfn.MAXIFS(Cleaned_Data!$G:$G,Cleaned_Data!$A:$A,$B47) -> 240303 | G47: =SUMIF(Cleaned_Data!$A:$A,$B47,Cleaned_Data!$F:$F) -> 819
B48: Pfizer | C48: =COUNTIF(Cleaned_Data!$A:$A,$B48) -> 10 | D48: =AVERAGEIF(Cleaned_Data!$A:$A,$B48,Cleaned_Data!$G:$G) -> 141828.2 | E48: =_xlfn.MINIFS(Cleaned_Data!$G:$G,Cleaned_Data!$A:$A,$B48) -> 81354 | F48: =_xlfn.MAXIFS(Cleaned_Data!$G:$G,Cleaned_Data!$A:$A,$B48) -> 209548 | G48: =SUMIF(Cleaned_Data!$A:$A,$B48,Cleaned_Data!$F:$F) -> 61
B49: Lyft Drivers | C49: =COUNTIF(Cleaned_Data!$A:$A,$B49) -> 10 | D49: =AVERAGEIF(Cleaned_Data!$A:$A,$B49,Cleaned_Data!$G:$G) -> 134491.48 | E49: =_xlfn.MINIFS(Cleaned_Data!$G:$G,Cleaned_Data!$A:$A,$B49) -> 48173 | F49: =_xlfn.MAXIFS(Cleaned_Data!$G:$G,Cleaned_Data!$A:$A,$B49) -> 369439 | G49: =SUMIF(Cleaned_Data!$A:$A,$B49,Cleaned_Data!$F:$F) -> 66
B50: Meta | C50: =COUNTIF(Cleaned_Data!$A:$A,$B50) -> 10 | D50: =AVERAGEIF(Cleaned_Data!$A:$A,$B50,Cleaned_Data!$G:$G) -> 134460.34 | E50: =_xlfn.MINIFS(Cleaned_Data!$G:$G,Cleaned_Data!$A:$A,$B50) -> 55452.8 | F50: =_xlfn.MAXIFS(Cleaned_Data!$G:$G,Cleaned_Data!$A:$A,$B50) -> 228480 | G50: =SUMIF(Cleaned_Data!$A:$A,$B50,Cleaned_Data!$F:$F) -> 112
B51: Ford Motor Company | C51: =COUNTIF(Cleaned_Data!$A:$A,$B51) -> 10 | D51: =AVERAGEIF(Cleaned_Data!$A:$A,$B51,Cleaned_Data!$G:$G) -> 133518.6 | E51: =_xlfn.MINIFS(Cleaned_Data!$G:$G,Cleaned_Data!$A:$A,$B51) -> 75982 | F51: =_xlfn.MAXIFS(Cleaned_Data!$G:$G,Cleaned_Data!$A:$A,$B51) -> 213667 | G51: =SUMIF(Cleaned_Data!$A:$A,$B51,Cleaned_Data!$F:$F) -> 79
... B137: Panera Bread | C137: =COUNTIF(Cleaned_Data!$A:$A,$B137) -> 10 | D137: =AVERAGEIF(Cleaned_Data!$A:$A,$B137,Cleaned_Data!$G:$G) -> 29660.8 | E137: =_xlfn.MINIFS(Cleaned_Data!$G:$G,Cleaned_Data!$A:$A,$B137) -> 22963.2 | F137: =_xlfn.MAXIFS(Cleaned_Data!$G:$G,Cleaned_Data!$A:$A,$B137) -> 34860.8 | G137: =SUMIF(Cleaned_Data!$A:$A,$B137,Cleaned_Data!$F:$F) -> 631

Sheet What_If_Analysis
B2: What-If Analysis
B3: Raise-percentage sensitivity table, Goal Seek setup, and Scenario Manager setup.
B5: 1. Sensitivity table — raise % vs. new annual salary
B7: Selected job (Company|JobTitle key): | D7: 7-Eleven|Assistant Manager
B8: Base Annual Salary: | D8: =IFERROR(INDEX(Cleaned_Data!$G:$G,MATCH(D7,Cleaned_Data!$H:$H,0)),"No match") -> 36275.2
B10: Raise % | C10: New Annual Salary
B11: 0 | C11: =$D$8*(1+B11) -> 36275.2
B12: 0.02 | C12: =$D$8*(1+B12) -> 37000.704
B13: 0.05 | C13: =$D$8*(1+B13) -> 38088.96
B14: 0.08 | C14: =$D$8*(1+B14) -> 39177.216
B15: 0.1 | C15: =$D$8*(1+B15) -> 39902.72
B16: 0.15 | C16: =$D$8*(1+B16) -> 41716.48
B17: 0.2 | C17: =$D$8*(1+B17) -> 43530.24
B21: 2. Goal Seek — what raise % hits a target salary?
B23: Current Annual Salary: | D23: =D8 -> 36275.2
B24: Target Annual Salary: | D24: 75000
B25: Required Raise % (Goal Seek solves this): | D25: 0
B26: New Annual Salary (Set cell for Goal Seek): | D26: =D23*(1+D25) -> 36275.2
B30: 3. Scenario Manager — Conservative / Moderate / Aggressive raises
B33: Scenario | C33: Raise %
B34: Conservative | C34: 0.02
B35: Moderate | C35: 0.05
B36: Aggressive | C36: 0.1

Sheet Dashboard
B2: Salary Dashboard
B3: KPI cards, a company selector, and summary charts. The VBA macro RefreshDashboard() rebuilds this sheet.
B5: Total Records | D5: Companies | F5: Categories | H5: Avg Annual Salary
B6: =COUNTA(Cleaned_Data!A2:A980) -> 979 | D6: =SUMPRODUCT(1/COUNTIF(Cleaned_Data!A2:A980,Cleaned_Data!A2:A980)) -> 98 | F6: =SUMPRODUCT(1/COUNTIF(Cleaned_Data!B2:B980,Cleaned_Data!B2:B980)) -> 29 | H6: =AVERAGE(Cleaned_Data!G2:G980) -> 84157.883
B9: Company Selector
B11: Company: | C11: 7-Eleven
B12: Job Titles at this Company: | C12: =COUNTIF(Cleaned_Data!$A:$A,C11) -> 10
B13: Avg Annual Salary here: | C13: =AVERAGEIF(Cleaned_Data!$A:$A,C11,Cleaned_Data!$G:$G) -> 62034
B16: Category | C16: Avg Annual Salary
B17: =Pivot_Summary!B7 -> Arts & Entertainment | C17: =Pivot_Summary!D7 -> 163041
B18: =Pivot_Summary!B8 -> IT Operations & Helpdesk | C18: =Pivot_Summary!D8 -> 159714.7
B19: =Pivot_Summary!B9 -> Project Management | C19: =Pivot_Summary!D9 -> 154863.33
B20: =Pivot_Summary!B10 -> Software Development | C20: =Pivot_Summary!D10 -> 129481.72
B21: =Pivot_Summary!B11 -> Marketing | C21: =Pivot_Summary!D11 -> 118235.29
B22: =Pivot_Summary!B12 -> Management | C22: =Pivot_Summary!D12 -> 114841.14
B23: =Pivot_Summary!B13 -> Information Design & Documentation | C23: =Pivot_Summary!D13 -> 114279.57
B24: =Pivot_Summary!B14 -> Mathematics | C24: =Pivot_Summary!D14 -> 110308.44
B25: =Pivot_Summary!B15 -> Medical Technician | C25: =Pivot_Summary!D15 -> 98360.08
B26: =Pivot_Summary!B16 -> Sales | C26: =Pivot_Summary!D16 -> 97496.628
B27: =Pivot_Summary!B17 -> Banking & Finance | C27: =Pivot_Summary!D17 -> 97344.58
B28: =Pivot_Summary!B18 -> Administrative Assistance | C28: =Pivot_Summary!D18 -> 91487.713
B31: Company | C31: Avg Annual Salary
B32: =Pivot_Summary!B40 -> Adobe | C32: =Pivot_Summary!D40 -> 213921.44
B33: =Pivot_Summary!B41 -> Airbnb | C33: =Pivot_Summary!D41 -> 197383.7
B34: =Pivot_Summary!B42 -> Salesforce | C34: =Pivot_Summary!D42 -> 195886.4
B35: =Pivot_Summary!B43 -> PayPal | C35: =Pivot_Summary!D43 -> 162608.6
B36: =Pivot_Summary!B44 -> Intel Corporation | C36: =Pivot_Summary!D44 -> 156559.8
B37: =Pivot_Summary!B45 -> Tesla | C37: =Pivot_Summary!D45 -> 151997.06
B38: =Pivot_Summary!B46 -> Dell Technologies | C38: =Pivot_Summary!D46 -> 148389.7
B39: =Pivot_Summary!B47 -> EY | C39: =Pivot_Summary!D47 -> 145721.3
B40: =Pivot_Summary!B48 -> Pfizer | C40: =Pivot_Summary!D48 -> 141828.2
B41: =Pivot_Summary!B49 -> Lyft Drivers | C41: =Pivot_Summary!D49 -> 134491.48
B42: =Pivot_Summary!B50 -> Meta | C42: =Pivot_Summary!D50 -> 134460.34
B43: =Pivot_Summary!B51 -> Ford Motor Company | C43: =Pivot_Summary!D51 -> 133518.6

Sheet VBA_Macros
B2: VBA Macros — Source Code & Setup
B3: Copy each Sub into its own Module in the VBA editor (Alt+F11). See setup steps at the bottom.
B5: Macro 1 — CleanAndConvertSalaries (data cleaning)
B6: Sub CleanAndConvertSalaries()
B7: ' Reads Raw_Data, converts every salary to an annual figure,
B8: ' and (re)writes the Cleaned_Data sheet from scratch.
B9: Dim wsRaw As Worksheet, wsClean As Worksheet
B10: Dim lastRow As Long, i As Long, outRow As Long
B11: Dim period As String, salary As Double, mult As Double
B13: Set wsRaw = ThisWorkbook.Sheets("Raw_Data")
B14: Set wsClean = ThisWorkbook.Sheets("Cleaned_Data")
B16: lastRow = wsRaw.Cells(wsRaw.Rows.Count, "A").End(xlUp).Row
... B153: 9. Save the .xlsm. Every time you reopen it, click 'Enable Content' on the yellow security bar to allow the macros to run.
